Workbook

Sheet Paramètres
B2: PLANNING DE STAFF — SÉMI RAGNAROK · 18–19 septembre 2026
B5: ÉQUIPES | C5: Effectif | D5: Filles | E5: Garçons | F5: Chef d'équipe | G5: POSTE | H5: Remarque / responsable | J5: CRÉNEAUX
B6: Équipe 1 | C6: =COUNTA(B$15:B$22) -> 5 | D6: =COUNTIFS($C$26:$C$65,$B6,$D$26:$D$65,"F") -> 4 | E6: =COUNTIFS($C$26:$C$65,$B6,$D$26:$D$65,"G") -> 1 | F6: Célie | G6: SÉCU | J6: 04h–05h
B7: Équipe 2 | C7: =COUNTA(C$15:C$22) -> 5 | D7: =COUNTIFS($C$26:$C$65,$B7,$D$26:$D$65,"F") -> 2 | E7: =COUNTIFS($C$26:$C$65,$B7,$D$26:$D$65,"G") -> 3 | F7: Léna | G7: PLAINE | J7: 05h–06h
B8: Équipe 3 | C8: =COUNTA(D$15:D$22) -> 5 | D8: =COUNTIFS($C$26:$C$65,$B8,$D$26:$D$65,"F") -> 3 | E8: =COUNTIFS($C$26:$C$65,$B8,$D$26:$D$65,"G") -> 2 | F8: Maryline | G8: SURVEILLANCE ACTIVITÉ | J8: 06h–07h
B9: Équipe 4 | C9: =COUNTA(E$15:E$22) -> 5 | D9: =COUNTIFS($C$26:$C$65,$B9,$D$26:$D$65,"F") -> 2 | E9: =COUNTIFS($C$26:$C$65,$B9,$D$26:$D$65,"G") -> 3 | F9: Marthe | G9: PRÉPA OB | J9: 07h–08h
B10: Équipe 5 | C10: =COUNTA(F$15:F$22) -> 4 | D10: =COUNTIFS($C$26:$C$65,$B10,$D$26:$D$65,"F") -> 1 | E10: =COUNTIFS($C$26:$C$65,$B10,$D$26:$D$65,"G") -> 3 | F10: Nathan | G10: REPAS | J10: 08h–09h
G11: BUVETTE | J11: 09h–10h
G12: NAVETTES | J12: 10h–11h
B13: COMPOSITION DES ÉQUIPES | G13: PRÉCHECK | J13: 11h–12h
B14: =$B$6 -> Équipe 1 | C14: =$B$7 -> Équipe 2 | D14: =$B$8 -> Équipe 3 | E14: =$B$9 -> Équipe 4 | F14: =$B$10 -> Équipe 5 | G14: SMAT 1 (VOIR STAFF RS) | J14: 12h–13h
B15: Célie | C15: Léna | D15: Maryline | E15: Marthe | F15: Nathan | G15: SMAT 1 (VOIR STAFF RS) | J15: 13h–14h
B16: Colombe | C16: Léo-Paul | D16: Maelle | E16: Louis | F16: Aurélien | G16: FOUILLES | J16: 14h–15h
B17: Camille | C17: Macéo | D17: Malia | E17: Léa | F17: Benoit | G17: DÉPART GHYVELDE | J17: 15h–16h
B18: Lucien | C18: Samuel | D18: Gatien | E18: Adrien | F18: Amélie | G18: DÉFILÉ DES ASSOS | J18: 16h–17h
B19: Blanche | C19: Zoé | D19: Teddy | E19: Ulysse | G19: MONTAGE / RANGEMENT | J19: 17h–18h
G20: REPOS | J20: 18h–19h
J21: 19h–20h
J22: 20h–21h
J23: 21h–22h
B24: STAFF | J24: 22h–23h
B25: Nom | C25: Équipe (auto) | D25: Genre (F/G) | E25: Téléphone | F25: Placé ? | J25: 23h–00h
B26: Camille | C26: =IF(COUNTIF($B$15:$F$22,$B26)<>1,"",INDEX($B$14:$F$14,SUMPRODUCT(($B$15:$F$22=$B26)*(COLUMN($B$15:$F$22)-COLUMN($B$15)+1)))) -> Équipe 1 | D26: F | F26: =IF($B26="","",IF(COUNTIF($B$15:$F$22,$B26)=1,"✔",IF(COUNTIF($B$15:$F$22,$B26)=0,"⚠ non placé","⚠ en double"))) -> ✔ | J26: 00h–01h
B27: Colombe | C27: =IF(COUNTIF($B$15:$F$22,$B27)<>1,"",INDEX($B$14:$F$14,SUMPRODUCT(($B$15:$F$22=$B27)*(COLUMN($B$15:$F$22)-COLUMN($B$15)+1)))) -> Équipe 1 | D27: F | F27: =IF($B27="","",IF(COUNTIF($B$15:$F$22,$B27)=1,"✔",IF(COUNTIF($B$15:$F$22,$B27)=0,"⚠ non placé","⚠ en double"))) -> ✔ | J27: 01h–02h
B28: Célie | C28: =IF(COUNTIF($B$15:$F$22,$B28)<>1,"",INDEX($B$14:$F$14,SUMPRODUCT(($B$15:$F$22=$B28)*(COLUMN($B$15:$F$22)-COLUMN($B$15)+1)))) -> Équipe 1 | D28: F | F28: =IF($B28="","",IF(COUNTIF($B$15:$F$22,$B28)=1,"✔",IF(COUNTIF($B$15:$F$22,$B28)=0,"⚠ non placé","⚠ en double"))) -> ✔ | J28: 02h–03h
B29: Lucien | C29: =IF(COUNTIF($B$15:$F$22,$B29)<>1,"",INDEX($B$14:$F$14,SUMPRODUCT(($B$15:$F$22=$B29)*(COLUMN($B$15:$F$22)-COLUMN($B$15)+1)))) -> Équipe 1 | D29: G | F29: =IF($B29="","",IF(COUNTIF($B$15:$F$22,$B29)=1,"✔",IF(COUNTIF($B$15:$F$22,$B29)=0,"⚠ non placé","⚠ en double"))) -> ✔ | J29: 03h–04h
B30: Nathan | C30: =IF(COUNTIF($B$15:$F$22,$B30)<>1,"",INDEX($B$14:$F$14,SUMPRODUCT(($B$15:$F$22=$B30)*(COLUMN($B$15:$F$22)-COLUMN($B$15)+1)))) -> Équipe 5 | D30: G | F30: =IF($B30="","",IF(COUNTIF($B$15:$F$22,$B30)=1,"✔",IF(COUNTIF($B$15:$F$22,$B30)=0,"⚠ non placé","⚠ en double"))) -> ✔
B31: Léna | C31: =IF(COUNTIF($B$15:$F$22,$B31)<>1,"",INDEX($B$14:$F$14,SUMPRODUCT(($B$15:$F$22=$B31)*(COLUMN($B$15:$F$22)-COLUMN($B$15)+1)))) -> Équipe 2 | D31: F | F31: =IF($B31="","",IF(COUNTIF($B$15:$F$22,$B31)=1,"✔",IF(COUNTIF($B$15:$F$22,$B31)=0,"⚠ non placé","⚠ en double"))) -> ✔
B32: Léo-Paul | C32: =IF(COUNTIF($B$15:$F$22,$B32)<>1,"",INDEX($B$14:$F$14,SUMPRODUCT(($B$15:$F$22=$B32)*(COLUMN($B$15:$F$22)-COLUMN($B$15)+1)))) -> Équipe 2 | D32: G | F32: =IF($B32="","",IF(COUNTIF($B$15:$F$22,$B32)=1,"✔",IF(COUNTIF($B$15:$F$22,$B32)=0,"⚠ non placé","⚠ en double"))) -> ✔
B33: Macéo | C33: =IF(COUNTIF($B$15:$F$22,$B33)<>1,"",INDEX($B$14:$F$14,SUMPRODUCT(($B$15:$F$22=$B33)*(COLUMN($B$15:$F$22)-COLUMN($B$15)+1)))) -> Équipe 2 | D33: G | F33: =IF($B33="","",IF(COUNTIF($B$15:$F$22,$B33)=1,"✔",IF(COUNTIF($B$15:$F$22,$B33)=0,"⚠ non placé","⚠ en double"))) -> ✔
B34: Samuel | C34: =IF(COUNTIF($B$15:$F$22,$B34)<>1,"",INDEX($B$14:$F$14,SUMPRODUCT(($B$15:$F$22=$B34)*(COLUMN($B$15:$F$22)-COLUMN($B$15)+1)))) -> Équipe 2 | D34: G | F34: =IF($B34="","",IF(COUNTIF($B$15:$F$22,$B34)=1,"✔",IF(COUNTIF($B$15:$F$22,$B34)=0,"⚠ non placé","⚠ en double"))) -> ✔
B35: Zoé | C35: =IF(COUNTIF($B$15:$F$22,$B35)<>1,"",INDEX($B$14:$F$14,SUMPRODUCT(($B$15:$F$22=$B35)*(COLUMN($B$15:$F$22)-COLUMN($B$15)+1)))) -> Équipe 2 | D35: F | F35: =IF($B35="","",IF(COUNTIF($B$15:$F$22,$B35)=1,"✔",IF(COUNTIF($B$15:$F$22,$B35)=0,"⚠ non placé","⚠ en double"))) -> ✔
B36: Gatien | C36: =IF(COUNTIF($B$15:$F$22,$B36)<>1,"",INDEX($B$14:$F$14,SUMPRODUCT(($B$15:$F$22=$B36)*(COLUMN($B$15:$F$22)-COLUMN($B$15)+1)))) -> Équipe 3 | D36: G | F36: =IF($B36="","",IF(COUNTIF($B$15:$F$22,$B36)=1,"✔",IF(COUNTIF($B$15:$F$22,$B36)=0,"⚠ non placé","⚠ en double"))) -> ✔
B37: Maelle | C37: =IF(COUNTIF($B$15:$F$22,$B37)<>1,"",INDEX($B$14:$F$14,SUMPRODUCT(($B$15:$F$22=$B37)*(COLUMN($B$15:$F$22)-COLUMN($B$15)+1)))) -> Équipe 3 | D37: F | F37: =IF($B37="","",IF(COUNTIF($B$15:$F$22,$B37)=1,"✔",IF(COUNTIF($B$15:$F$22,$B37)=0,"⚠ non placé","⚠ en double"))) -> ✔
B38: Malia | C38: =IF(COUNTIF($B$15:$F$22,$B38)<>1,"",INDEX($B$14:$F$14,SUMPRODUCT(($B$15:$F$22=$B38)*(COLUMN($B$15:$F$22)-COLUMN($B$15)+1)))) -> Équipe 3 | D38: F | F38: =IF($B38="","",IF(COUNTIF($B$15:$F$22,$B38)=1,"✔",IF(COUNTIF($B$15:$F$22,$B38)=0,"⚠ non placé","⚠ en double"))) -> ✔
B39: Maryline | C39: =IF(COUNTIF($B$15:$F$22,$B39)<>1,"",INDEX($B$14:$F$14,SUMPRODUCT(($B$15:$F$22=$B39)*(COLUMN($B$15:$F$22)-COLUMN($B$15)+1)))) -> Équipe 3 | D39: F | F39: =IF($B39="","",IF(COUNTIF($B$15:$F$22,$B39)=1,"✔",IF(COUNTIF($B$15:$F$22,$B39)=0,"⚠ non placé","⚠ en double"))) -> ✔
B40: Teddy | C40: =IF(COUNTIF($B$15:$F$22,$B40)<>1,"",INDEX($B$14:$F$14,SUMPRODUCT(($B$15:$F$22=$B40)*(COLUMN($B$15:$F$22)-COLUMN($B$15)+1)))) -> Équipe 3 | D40: G | F40: =IF($B40="","",IF(COUNTIF($B$15:$F$22,$B40)=1,"✔",IF(COUNTIF($B$15:$F$22,$B40)=0,"⚠ non placé","⚠ en double"))) -> ✔
B41: Adrien | C41: =IF(COUNTIF($B$15:$F$22,$B41)<>1,"",INDEX($B$14:$F$14,SUMPRODUCT(($B$15:$F$22=$B41)*(COLUMN($B$15:$F$22)-COLUMN($B$15)+1)))) -> Équipe 4 | D41: G | F41: =IF($B41="","",IF(COUNTIF($B$15:$F$22,$B41)=1,"✔",IF(COUNTIF($B$15:$F$22,$B41)=0,"⚠ non placé","⚠ en double"))) -> ✔
... B49: Blanche | C49: =IF(COUNTIF($B$15:$F$22,$B49)<>1,"",INDEX($B$14:$F$14,SUMPRODUCT(($B$15:$F$22=$B49)*(COLUMN($B$15:$F$22)-COLUMN($B$15)+1)))) -> Équipe 1 | D49: F | F49: =IF($B49="","",IF(COUNTIF($B$15:$F$22,$B49)=1,"✔",IF(COUNTIF($B$15:$F$22,$B49)=0,"⚠ non placé","⚠ en double"))) -> ✔
C50: =IF(COUNTIF($B$15:$F$22,$B50)<>1,"",INDEX($B$14:$F$14,SUMPRODUCT(($B$15:$F$22=$B50)*(COLUMN($B$15:$F$22)-COLUMN($B$15)+1)))) | F50: =IF($B50="","",IF(COUNTIF($B$15:$F$22,$B50)=1,"✔",IF(COUNTIF($B$15:$F$22,$B50)=0,"⚠ non placé","⚠ en double")))
...

Sheet J1 — VEN 18
A1: VENDREDI 18 SEPTEMBRE 2026
A4: CRÉNEAU | B4: PROGRAMME DE LA JOURNÉE | C4: =Paramètres!$B$6&IF(Paramètres!$F$6="","",CHAR(10)&"Chef : "&Paramètres!$F$6) -> Équipe 1 Chef : Célie | D4: =Paramètres!$B$7&IF(Paramètres!$F$7="","",CHAR(10)&"Chef : "&Paramètres!$F$7) -> Équipe 2 Chef : Léna | E4: =Paramètres!$B$8&IF(Paramètres!$F$8="","",CHAR(10)&"Chef : "&Paramètres!$F$8) -> Équipe 3 Chef : Maryline | F4: =Paramètres!$B$9&IF(Paramètres!$F$9="","",CHAR(10)&"Chef : "&Paramètres!$F$9) -> Équipe 4 Chef : Marthe | G4: =Paramètres!$B$10&IF(Paramètres!$F$10="","",CHAR(10)&"Chef : "&Paramètres!$F$10) -> Équipe 5 Chef : Nathan | H4: ÉQUIPES RÉVEILLÉES
A5: 04h–05h | H5: =IF(COUNTA(C5:G5)=0,"—",COUNTA(C5:G5)-COUNTIF(C5:G5,"REPOS")) -> —
A6: 05h–06h | B6: RDV 5h30 Pour tout préparer avant l'arriver des cotisants | C6: MONTAGE / RANGEMENT | D6: MONTAGE / RANGEMENT | E6: MONTAGE / RANGEMENT | F6: MONTAGE / RANGEMENT | G6: MONTAGE / RANGEMENT | H6: =IF(COUNTA(C6:G6)=0,"—",COUNTA(C6:G6)-COUNTIF(C6:G6,"REPOS")) -> 5
A7: 06h–07h | B7: 06h30 RDV à l'EDHEC — Précheck Sémi GROUPE 1 | C7: PRÉCHECK | D7: PRÉCHECK | E7: PRÉCHECK | F7: PRÉCHECK | G7: PRÉCHECK | H7: =IF(COUNTA(C7:G7)=0,"—",COUNTA(C7:G7)-COUNTIF(C7:G7,"REPOS")) -> 5
A8: 07h–08h | B8: 07h00 Précheck Sémi GROUPE 2 | C8: PRÉCHECK | D8: PRÉCHECK | E8: PRÉCHECK | F8: PRÉCHECK | G8: PRÉCHECK | H8: =IF(COUNTA(C8:G8)=0,"—",COUNTA(C8:G8)-COUNTIF(C8:G8,"REPOS")) -> 5
A9: 08h–09h | B9: 08h00–08h45 Défilé des associations | C9: DÉFILÉ DES ASSOS | D9: DÉFILÉ DES ASSOS | E9: DÉFILÉ DES ASSOS | F9: DÉFILÉ DES ASSOS | G9: DÉFILÉ DES ASSOS | H9: =IF(COUNTA(C9:G9)=0,"—",COUNTA(C9:G9)-COUNTIF(C9:G9,"REPOS")) -> 5
A10: 09h–10h | B10: 09h00 Diffusion boucle Groupe 1 + petit déjeuner | C10: DÉPART GHYVELDE | D10: DÉPART GHYVELDE | E10: DISTRIBUTION PET DEJ | F10: SÉCU | G10: SÉCU | H10: =IF(COUNTA(C10:G10)=0,"—",COUNTA(C10:G10)-COUNTIF(C10:G10,"REPOS")) -> 5
A11: 10h–11h | B11: 10h00 Diffusion boucle Groupe 2 + petit déjeuner | C11: PLAINE | D11: PLAINE | E11: SÉCU | F11: SÉCU | G11: SÉCU | H11: =IF(COUNTA(C11:G11)=0,"—",COUNTA(C11:G11)-COUNTIF(C11:G11,"REPOS")) -> 5
A12: 11h–12h | B12: 11h00 Départ 1re navette (jusqu'à 16h15) — distribution repas | C12: PLAINE | D12: PLAINE | E12: FOUILLES | F12: DISTRIBUTION REPAS | G12: NAVETTES | H12: =IF(COUNTA(C12:G12)=0,"—",COUNTA(C12:G12)-COUNTIF(C12:G12,"REPOS")) -> 5
A13: 12h–13h | B13: Navettes — arrivées et installation sur site | C13: MONTAGE / RANGEMENT | D13: MONTAGE / RANGEMENT | E13: FOUILLES | F13: FOUILLES | G13: NAVETTES | H13: =IF(COUNTA(C13:G13)=0,"—",COUNTA(C13:G13)-COUNTIF(C13:G13,"REPOS")) -> 5
A14: 13h–14h | B14: Navettes — arrivées et installation sur site | C14: NAVETTES | D14: PLAINE | E14: NAVETTES | F14: FOUILLES | G14: FOUILLES | H14: =IF(COUNTA(C14:G14)=0,"—",COUNTA(C14:G14)-COUNTIF(C14:G14,"REPOS")) -> 5
A15: 14h–15h | B15: Navettes — arrivées et installation sur site | C15: PRÉPA OB | D15: PRÉPA OB | E15: NAVETTES | F15: FOUILLES | G15: FOUILLES | H15: =IF(COUNTA(C15:G15)=0,"—",COUNTA(C15:G15)-COUNTIF(C15:G15,"REPOS")) -> 5
A16: 15h–16h | B16: Navettes — dernières rotations | C16: PRÉPA OB | D16: PRÉPA OB | E16: FOUILLES | F16: NAVETTES | G16: FOUILLES | H16: =IF(COUNTA(C16:G16)=0,"—",COUNTA(C16:G16)-COUNTIF(C16:G16,"REPOS")) -> 5
A17: 16h–17h | B17: 16h00 BDS — tir à la corde & balle au prisonnier | C17: REPOS | D17: SURVEILLANCE ACTIVITÉ | E17: DÉPART GHYVELDE | F17: DÉPART GHYVELDE | G17: DÉPART GHYVELDE | H17: =IF(COUNTA(C17:G17)=0,"—",COUNTA(C17:G17)-COUNTIF(C17:G17,"REPOS")) -> 4
... A20: 19h–20h | B20: 19h00 ECC Mölkky x SUNSET 1-2-3 Soleil | C20: SÉCU | D20: PLAINE | E20: REPAS | F20: REPOS | G20: SURVEILLANCE ACTIVITÉ | H20: =IF(COUNTA(C20:G20)=0,"—",COUNTA(C20:G20)-COUNTIF(C20:G20,"REPOS")) -> 4
A21: 20h–21h | C21: PLAINE | D21: SÉCU | E21: REPAS | F21: SÉCU | G21: REPOS | H21: =IF(COUNTA(C21:G21)=0,"—",COUNTA(C21:G21)-COUNTIF(C21:G21,"REPOS")) -> 4
A22: 21h–22h | B22: Prépaparation arrivé Artiste et showcase | C22: SHOWCASE | D22: SHOWCASE | E22: SHOWCASE | F22: SHOWCASE | G22: SHOWCASE | H22: =IF(COUNTA(C22:G22)=0,"—",COUNTA(C22:G22)-COUNTIF(C22:G22,"REPOS")) -> 5
A23: 22h–23h | B23: 22h00 Showcase artiste sur la plaine · fermeture de la buvette | C23: SMAT 1 (VOIR STAFF RS) | D23: SMAT 1 (VOIR STAFF RS) | E23: SMAT 1 (VOIR STAFF RS) | F23: SMAT 1 (VOIR STAFF RS) | G23: SMAT 1 (VOIR STAFF RS) | H23: =IF(COUNTA(C23:G23)=0,"—",COUNTA(C23:G23)-COUNTIF(C23:G23,"REPOS")) -> 5
A24: 23h–00h | B24: 23h00 SMAT | C24: SMAT 1 (VOIR STAFF RS) | D24: SMAT 1 (VOIR STAFF RS) | E24: SMAT 1 (VOIR STAFF RS) | F24: SMAT 1 (VOIR STAFF RS) | G24: SMAT 1 (VOIR STAFF RS) | H24: =IF(COUNTA(C24:G24)=0,"—",COUNTA(C24:G24)-COUNTIF(C24:G24,"REPOS")) -> 5
A25: 00h–01h | C25: SMAT 1 (VOIR STAFF RS) | D25: SMAT 1 (VOIR STAFF RS) | E25: SMAT 1 (VOIR STAFF RS) | F25: SMAT 1 (VOIR STAFF RS) | G25: SMAT 1 (VOIR STAFF RS) | H25: =IF(COUNTA(C25:G25)=0,"—",COUNTA(C25:G25)-COUNTIF(C25:G25,"REPOS")) -> 5
A26: 01h–02h | C26: SMAT 1 (VOIR STAFF RS) | D26: SMAT 1 (VOIR STAFF RS) | E26: SMAT 1 (VOIR STAFF RS) | F26: SMAT 1 (VOIR STAFF RS) | G26: SMAT 1 (VOIR STAFF RS) | H26: =IF(COUNTA(C26:G26)=0,"—",COUNTA(C26:G26)-COUNTIF(C26:G26,"REPOS")) -> 5
A27: 02h–03h | C27: REPOS | D27: SMAT 1 (VOIR STAFF RS) | E27: SMAT 1 (VOIR STAFF RS) | F27: SMAT 1 (VOIR STAFF RS) | G27: REPOS | H27: =IF(COUNTA(C27:G27)=0,"—",COUNTA(C27:G27)-COUNTIF(C27:G27,"REPOS")) -> 3
A28: 03h–04h | B28: 03h00–05h00 After tech Ad'lib · 04h00 fin de journée | C28: REPOS | D28: REPOS | E28: REPOS | F28: REPOS | G28: REPOS | H28: =IF(COUNTA(C28:G28)=0,"—",COUNTA(C28:G28)-COUNTIF(C28:G28,"REPOS")) -> 0
A30: Total heures de poste par équipe | C30: =COUNTA(C5:C28)-COUNTIF(C5:C28,"REPOS") -> 20 | D30: =COUNTA(D5:D28)-COUNTIF(D5:D28,"REPOS") -> 21 | E30: =COUNTA(E5:E28)-COUNTIF(E5:E28,"REPOS") -> 22 | F30: =COUNTA(F5:F28)-COUNTIF(F5:F28,"REPOS") -> 20 | G30: =COUNTA(G5:G28)-COUNTIF(G5:G28,"REPOS") -> 20

Sheet J2 — SAM 19
A1: SAMEDI 19 SEPTEMBRE 2026
A4: CRÉNEAU | B4: PROGRAMME DE LA JOURNÉE | C4: =Paramètres!$B$6&IF(Paramètres!$F$6="","",CHAR(10)&"Chef : "&Paramètres!$F$6) -> Équipe 1 Chef : Célie | D4: =Paramètres!$B$7&IF(Paramètres!$F$7="","",CHAR(10)&"Chef : "&Paramètres!$F$7) -> Équipe 2 Chef : Léna | E4: =Paramètres!$B$8&IF(Paramètres!$F$8="","",CHAR(10)&"Chef : "&Paramètres!$F$8) -> Équipe 3 Chef : Maryline | F4: =Paramètres!$B$9&IF(Paramètres!$F$9="","",CHAR(10)&"Chef : "&Paramètres!$F$9) -> Équipe 4 Chef : Marthe | G4: =Paramètres!$B$10&IF(Paramètres!$F$10="","",CHAR(10)&"Chef : "&Paramètres!$F$10) -> Équipe 5 Chef : Nathan | H4: ÉQUIPES RÉVEILLÉES
A5: 04h–05h | C5: REPOS | D5: REPOS | E5: REPOS | F5: REPOS | G5: REPOS | H5: =IF(COUNTA(C5:G5)=0,"—",COUNTA(C5:G5)-COUNTIF(C5:G5,"REPOS")) -> 0
A6: 05h–06h | C6: REPOS | D6: REPOS | E6: REPOS | F6: REPOS | G6: SÉCU | H6: =IF(COUNTA(C6:G6)=0,"—",COUNTA(C6:G6)-COUNTIF(C6:G6,"REPOS")) -> 1
A7: 06h–07h | C7: SÉCU | D7: REPOS | E7: REPOS | F7: REPOS | G7: REPOS | H7: =IF(COUNTA(C7:G7)=0,"—",COUNTA(C7:G7)-COUNTIF(C7:G7,"REPOS")) -> 1
A8: 07h–08h | C8: REPOS | D8: SÉCU | E8: REPOS | F8: REPOS | G8: REPOS | H8: =IF(COUNTA(C8:G8)=0,"—",COUNTA(C8:G8)-COUNTIF(C8:G8,"REPOS")) -> 1
A9: 08h–09h | B9: 08h00–11h00 Distribution petit déjeuner | C9: REPOS | D9: REPOS | E9: SÉCU | F9: DISTRIBUTION PET DEJ | G9: REPOS | H9: =IF(COUNTA(C9:G9)=0,"—",COUNTA(C9:G9)-COUNTIF(C9:G9,"REPOS")) -> 2
A10: 09h–10h | B10: Petit déjeuner | C10: REPOS | D10: REPOS | E10: REPOS | F10: DISTRIBUTION PET DEJ | G10: SÉCU | H10: =IF(COUNTA(C10:G10)=0,"—",COUNTA(C10:G10)-COUNTIF(C10:G10,"REPOS")) -> 2
A11: 10h–11h | B11: Petit déjeuner | C11: REPOS | D11: REPOS | E11: OUVERTURE BUVETTE | F11: DISTRIBUTION PET DEJ | G11: REPAS | H11: =IF(COUNTA(C11:G11)=0,"—",COUNTA(C11:G11)-COUNTIF(C11:G11,"REPOS")) -> 3
A12: 11h–12h | B12: 11h00 Ouverture buvette · Ventriglisse par EJM · ouverture déjeuner grange | C12: SURVEILLANCE ACTIVITÉ | D12: REPOS | E12: SURVEILLANCE ACTIVITÉ | F12: SÉCU | G12: REPAS | H12: =IF(COUNTA(C12:G12)=0,"—",COUNTA(C12:G12)-COUNTIF(C12:G12,"REPOS")) -> 4
A13: 12h–13h | B13: 11h00–14h00 Déjeuner dans la grange | C13: REPAS | D13: SÉCU | E13: SURVEILLANCE ACTIVITÉ | F13: REPOS | G13: REPAS | H13: =IF(COUNTA(C13:G13)=0,"—",COUNTA(C13:G13)-COUNTIF(C13:G13,"REPOS")) -> 4
A14: 13h–14h | B14: Ventriglisse (jusqu'à 13h) / déjeuner grange | C14: REPAS | D14: SÉCU | E14: SURVEILLANCE ACTIVITÉ | F14: REPOS | G14: REPAS | H14: =IF(COUNTA(C14:G14)=0,"—",COUNTA(C14:G14)-COUNTIF(C14:G14,"REPOS")) -> 4
A15: 14h–15h | B15: 14h00 OJO relais bière x Gourm'edhec relais flambi | C15: PRÉPA OB | D15: PLAINE | E15: SURVEILLANCE ACTIVITÉ | F15: REPOS | G15: PRÉPA OB | H15: =IF(COUNTA(C15:G15)=0,"—",COUNTA(C15:G15)-COUNTIF(C15:G15,"REPOS")) -> 4
A16: 15h–16h | B16: 15h00 PDC open chips · Dionysos relais cubi · DJ contest étudiant (15h–16h30) | C16: PRÉPA OB | D16: PLAINE | E16: SÉCU | F16: SURVEILLANCE ACTIVITÉ | G16: PRÉPA OB | H16: =IF(COUNTA(C16:G16)=0,"—",COUNTA(C16:G16)-COUNTIF(C16:G16,"REPOS")) -> 5
A17: 16h–17h | B17: 16h00–17h00 Chti — distribution sangria | C17: SURVEILLANCE ACTIVITÉ | D17: SURVEILLANCE ACTIVITÉ | E17: SURVEILLANCE ACTIVITÉ | F17: SURVEILLANCE ACTIVITÉ | G17: SURVEILLANCE ACTIVITÉ | H17: =IF(COUNTA(C17:G17)=0,"—",COUNTA(C17:G17)-COUNTIF(C17:G17,"REPOS")) -> 5
A18: 17h–18h | B18: 17h00–18h00 CCE — distribution martini rouge | C18: SURVEILLANCE ACTIVITÉ | D18: SURVEILLANCE ACTIVITÉ | E18: SURVEILLANCE ACTIVITÉ | F18: SURVEILLANCE ACTIVITÉ | G18: SURVEILLANCE ACTIVITÉ | H18: =IF(COUNTA(C18:G18)=0,"—",COUNTA(C18:G18)-COUNTIF(C18:G18,"REPOS")) -> 5
A19: 18h–19h | B19: 18h00–21h00 Dîner dans la grange par association | C19: SURVEILLANCE ACTIVITÉ | D19: DISTRIBUTION PRÉCHAUFFE | E19: SÉCU | F19: REPAS | G19: REPOS | H19: =IF(COUNTA(C19:G19)=0,"—",COUNTA(C19:G19)-COUNTIF(C19:G19,"REPOS")) -> 4
A20: 19h–20h | B20: 19h00 OJO SKI — relais bière | C20: REPOS | D20: DISTRIBUTION PRÉCHAUFFE | E20: SURVEILLANCE ACTIVITÉ | F20: REPAS | G20: REPOS | H20: =IF(COUNTA(C20:G20)=0,"—",COUNTA(C20:G20)-COUNTIF(C20:G20,"REPOS")) -> 3
... A26: 01h–02h | B26: Navettes retour | C26: SMAT 2 (VOIR STAFF RS) | D26: SMAT 2 (VOIR STAFF RS) | E26: SMAT 2 (VOIR STAFF RS) | F26: SMAT 2 (VOIR STAFF RS) | G26: SMAT 2 (VOIR STAFF RS) | H26: =IF(COUNTA(C26:G26)=0,"—",COUNTA(C26:G26)-COUNTIF(C26:G26,"REPOS")) -> 5
A27: 02h–03h | C27: SMAT 2 (VOIR STAFF RS) | D27: SMAT 2 (VOIR STAFF RS) | E27: SMAT 2 (VOIR STAFF RS) | F27: SMAT 2 (VOIR STAFF RS) | G27: SMAT 2 (VOIR STAFF RS) | H27: =IF(COUNTA(C27:G27)=0,"—",COUNTA(C27:G27)-COUNTIF(C27:G27,"REPOS")) -> 5
A28: 03h–04h | B28: 04h00 Fin de journée | C28: RANGEMENT | D28: RANGEMENT | E28: RANGEMENT | F28: RANGEMENT | G28: RANGEMENT | H28: =IF(COUNTA(C28:G28)=0,"—",COUNTA(C28:G28)-COUNTIF(C28:G28,"REPOS")) -> 5
A30: Total heures de poste par équipe | C30: =COUNTA(C5:C28)-COUNTIF(C5:C28,"REPOS") -> 16 | D30: =COUNTA(D5:D28)-COUNTIF(D5:D28,"REPOS") -> 16 | E30: =COUNTA(E5:E28)-COUNTIF(E5:E28,"REPOS") -> 19 | F30: =COUNTA(F5:F28)-COUNTIF(F5:F28,"REPOS") -> 17 | G30: =COUNTA(G5:G28)-COUNTIF(G5:G28,"REPOS") -> 18

Sheet Fiche individuelle
B2: FICHE INDIVIDUELLE
B4: Ton nom : | C4: Colombe | E4: ← choisis un nom dans la liste
B5: Équipe : | C5: =IFERROR(INDEX(Paramètres!$C$26:$C$49,MATCH($C$4,Paramètres!$B$26:$B$49,0)),"") -> Équipe 1
B6: Coéquipiers : | C6: =IFERROR(_xlfn.TEXTJOIN(", ",TRUE(),$J$9:$J$32),"") -> Camille, Colombe, Célie, Lucien, Blanche
B7: Chef d'équipe : | C7: =IFERROR(INDEX(Paramètres!$F$6:$F$10,MATCH($C$5,Paramètres!$B$6:$B$10,0)),"") -> Célie
B9: CRÉNEAU | C9: VENDREDI 18 SEPT | D9: SAMEDI 19 SEPT | J9: =IF(Paramètres!$C$26=$C$5,Paramètres!$B$26,"") -> Camille
B10: 04h–05h | C10: =IFERROR(IF(INDEX('J1 — VEN 18'!$C$5:$G$28,1,MATCH($C$5,'J1 — VEN 18'!$C$4:$G$4,0))="","",INDEX('J1 — VEN 18'!$C$5:$G$28,1,MATCH($C$5,'J1 — VEN 18'!$C$4:$G$4,0))),"") | D10: =IFERROR(IF(INDEX('J2 — SAM 19'!$C$5:$G$28,1,MATCH($C$5,'J2 — SAM 19'!$C$4:$G$4,0))="","",INDEX('J2 — SAM 19'!$C$5:$G$28,1,MATCH($C$5,'J2 — SAM 19'!$C$4:$G$4,0))),"") | J10: =IF(Paramètres!$C$27=$C$5,Paramètres!$B$27,"") -> Colombe
B11: 05h–06h | C11: =IFERROR(IF(INDEX('J1 — VEN 18'!$C$5:$G$28,2,MATCH($C$5,'J1 — VEN 18'!$C$4:$G$4,0))="","",INDEX('J1 — VEN 18'!$C$5:$G$28,2,MATCH($C$5,'J1 — VEN 18'!$C$4:$G$4,0))),"") | D11: =IFERROR(IF(INDEX('J2 — SAM 19'!$C$5:$G$28,2,MATCH($C$5,'J2 — SAM 19'!$C$4:$G$4,0))="","",INDEX('J2 — SAM 19'!$C$5:$G$28,2,MATCH($C$5,'J2 — SAM 19'!$C$4:$G$4,0))),"") | J11: =IF(Paramètres!$C$28=$C$5,Paramètres!$B$28,"") -> Célie
B12: 06h–07h | C12: =IFERROR(IF(INDEX('J1 — VEN 18'!$C$5:$G$28,3,MATCH($C$5,'J1 — VEN 18'!$C$4:$G$4,0))="","",INDEX('J1 — VEN 18'!$C$5:$G$28,3,MATCH($C$5,'J1 — VEN 18'!$C$4:$G$4,0))),"") | D12: =IFERROR(IF(INDEX('J2 — SAM 19'!$C$5:$G$28,3,MATCH($C$5,'J2 — SAM 19'!$C$4:$G$4,0))="","",INDEX('J2 — SAM 19'!$C$5:$G$28,3,MATCH($C$5,'J2 — SAM 19'!$C$4:$G$4,0))),"") | J12: =IF(Paramètres!$C$29=$C$5,Paramètres!$B$29,"") -> Lucien
B13: 07h–08h | C13: =IFERROR(IF(INDEX('J1 — VEN 18'!$C$5:$G$28,4,MATCH($C$5,'J1 — VEN 18'!$C$4:$G$4,0))="","",INDEX('J1 — VEN 18'!$C$5:$G$28,4,MATCH($C$5,'J1 — VEN 18'!$C$4:$G$4,0))),"") | D13: =IFERROR(IF(INDEX('J2 — SAM 19'!$C$5:$G$28,4,MATCH($C$5,'J2 — SAM 19'!$C$4:$G$4,0))="","",INDEX('J2 — SAM 19'!$C$5:$G$28,4,MATCH($C$5,'J2 — SAM 19'!$C$4:$G$4,0))),"") | J13: =IF(Paramètres!$C$30=$C$5,Paramètres!$B$30,"")
B14: 08h–09h | C14: =IFERROR(IF(INDEX('J1 — VEN 18'!$C$5:$G$28,5,MATCH($C$5,'J1 — VEN 18'!$C$4:$G$4,0))="","",INDEX('J1 — VEN 18'!$C$5:$G$28,5,MATCH($C$5,'J1 — VEN 18'!$C$4:$G$4,0))),"") | D14: =IFERROR(IF(INDEX('J2 — SAM 19'!$C$5:$G$28,5,MATCH($C$5,'J2 — SAM 19'!$C$4:$G$4,0))="","",INDEX('J2 — SAM 19'!$C$5:$G$28,5,MATCH($C$5,'J2 — SAM 19'!$C$4:$G$4,0))),"") | J14: =IF(Paramètres!$C$31=$C$5,Paramètres!$B$31,"")
B15: 09h–10h | C15: =IFERROR(IF(INDEX('J1 — VEN 18'!$C$5:$G$28,6,MATCH($C$5,'J1 — VEN 18'!$C$4:$G$4,0))="","",INDEX('J1 — VEN 18'!$C$5:$G$28,6,MATCH($C$5,'J1 — VEN 18'!$C$4:$G$4,0))),"") | D15: =IFERROR(IF(INDEX('J2 — SAM 19'!$C$5:$G$28,6,MATCH($C$5,'J2 — SAM 19'!$C$4:$G$4,0))="","",INDEX('J2 — SAM 19'!$C$5:$G$28,6,MATCH($C$5,'J2 — SAM 19'!$C$4:$G$4,0))),"") | J15: =IF(Paramètres!$C$32=$C$5,Paramètres!$B$32,"")
B16: 10h–11h | C16: =IFERROR(IF(INDEX('J1 — VEN 18'!$C$5:$G$28,7,MATCH($C$5,'J1 — VEN 18'!$C$4:$G$4,0))="","",INDEX('J1 — VEN 18'!$C$5:$G$28,7,MATCH($C$5,'J1 — VEN 18'!$C$4:$G$4,0))),"") | D16: =IFERROR(IF(INDEX('J2 — SAM 19'!$C$5:$G$28,7,MATCH($C$5,'J2 — SAM 19'!$C$4:$G$4,0))="","",INDEX('J2 — SAM 19'!$C$5:$G$28,7,MATCH($C$5,'J2 — SAM 19'!$C$4:$G$4,0))),"") | J16: =IF(Paramètres!$C$33=$C$5,Paramètres!$B$33,"")
B17: 11h–12h | C17: =IFERROR(IF(INDEX('J1 — VEN 18'!$C$5:$G$28,8,MATCH($C$5,'J1 — VEN 18'!$C$4:$G$4,0))="","",INDEX('J1 — VEN 18'!$C$5:$G$28,8,MATCH($C$5,'J1 — VEN 18'!$C$4:$G$4,0))),"") | D17: =IFERROR(IF(INDEX('J2 — SAM 19'!$C$5:$G$28,8,MATCH($C$5,'J2 — SAM 19'!$C$4:$G$4,0))="","",INDEX('J2 — SAM 19'!$C$5:$G$28,8,MATCH($C$5,'J2 — SAM 19'!$C$4:$G$4,0))),"") | J17: =IF(Paramètres!$C$34=$C$5,Paramètres!$B$34,"")
B18: 12h–13h | C18: =IFERROR(IF(INDEX('J1 — VEN 18'!$C$5:$G$28,9,MATCH($C$5,'J1 — VEN 18'!$C$4:$G$4,0))="","",INDEX('J1 — VEN 18'!$C$5:$G$28,9,MATCH($C$5,'J1 — VEN 18'!$C$4:$G$4,0))),"") | D18: =IFERROR(IF(INDEX('J2 — SAM 19'!$C$5:$G$28,9,MATCH($C$5,'J2 — SAM 19'!$C$4:$G$4,0))="","",INDEX('J2 — SAM 19'!$C$5:$G$28,9,MATCH($C$5,'J2 — SAM 19'!$C$4:$G$4,0))),"") | J18: =IF(Paramètres!$C$35=$C$5,Paramètres!$B$35,"")
B19: 13h–14h | C19: =IFERROR(IF(INDEX('J1 — VEN 18'!$C$5:$G$28,10,MATCH($C$5,'J1 — VEN 18'!$C$4:$G$4,0))="","",INDEX('J1 — VEN 18'!$C$5:$G$28,10,MATCH($C$5,'J1 — VEN 18'!$C$4:$G$4,0))),"") | D19: =IFERROR(IF(INDEX('J2 — SAM 19'!$C$5:$G$28,10,MATCH($C$5,'J2 — SAM 19'!$C$4:$G$4,0))="","",INDEX('J2 — SAM 19'!$C$5:$G$28,10,MATCH($C$5,'J2 — SAM 19'!$C$4:$G$4,0))),"") | J19: =IF(Paramètres!$C$36=$C$5,Paramètres!$B$36,"")
B20: 14h–15h | C20: =IFERROR(IF(INDEX('J1 — VEN 18'!$C$5:$G$28,11,MATCH($C$5,'J1 — VEN 18'!$C$4:$G$4,0))="","",INDEX('J1 — VEN 18'!$C$5:$G$28,11,MATCH($C$5,'J1 — VEN 18'!$C$4:$G$4,0))),"") | D20: =IFERROR(IF(INDEX('J2 — SAM 19'!$C$5:$G$28,11,MATCH($C$5,'J2 — SAM 19'!$C$4:$G$4,0))="","",INDEX('J2 — SAM 19'!$C$5:$G$28,11,MATCH($C$5,'J2 — SAM 19'!$C$4:$G$4,0))),"") | J20: =IF(Paramètres!$C$37=$C$5,Paramètres!$B$37,"")
B21: 15h–16h | C21: =IFERROR(IF(INDEX('J1 — VEN 18'!$C$5:$G$28,12,MATCH($C$5,'J1 — VEN 18'!$C$4:$G$4,0))="","",INDEX('J1 — VEN 18'!$C$5:$G$28,12,MATCH($C$5,'J1 — VEN 18'!$C$4:$G$4,0))),"") | D21: =IFERROR(IF(INDEX('J2 — SAM 19'!$C$5:$G$28,12,MATCH($C$5,'J2 — SAM 19'!$C$4:$G$4,0))="","",INDEX('J2 — SAM 19'!$C$5:$G$28,12,MATCH($C$5,'J2 — SAM 19'!$C$4:$G$4,0))),"") | J21: =IF(Paramètres!$C$38=$C$5,Paramètres!$B$38,"")
B22: 16h–17h | C22: =IFERROR(IF(INDEX('J1 — VEN 18'!$C$5:$G$28,13,MATCH($C$5,'J1 — VEN 18'!$C$4:$G$4,0))="","",INDEX('J1 — VEN 18'!$C$5:$G$28,13,MATCH($C$5,'J1 — VEN 18'!$C$4:$G$4,0))),"") | D22: =IFERROR(IF(INDEX('J2 — SAM 19'!$C$5:$G$28,13,MATCH($C$5,'J2 — SAM 19'!$C$4:$G$4,0))="","",INDEX('J2 — SAM 19'!$C$5:$G$28,13,MATCH($C$5,'J2 — SAM 19'!$C$4:$G$4,0))),"") | J22: =IF(Paramètres!$C$39=$C$5,Paramètres!$B$39,"")
B23: 17h–18h | C23: =IFERROR(IF(INDEX('J1 — VEN 18'!$C$5:$G$28,14,MATCH($C$5,'J1 — VEN 18'!$C$4:$G$4,0))="","",INDEX('J1 — VEN 18'!$C$5:$G$28,14,MATCH($C$5,'J1 — VEN 18'!$C$4:$G$4,0))),"") | D23: =IFERROR(IF(INDEX('J2 — SAM 19'!$C$5:$G$28,14,MATCH($C$5,'J2 — SAM 19'!$C$4:$G$4,0))="","",INDEX('J2 — SAM 19'!$C$5:$G$28,14,MATCH($C$5,'J2 — SAM 19'!$C$4:$G$4,0))),"") | J23: =IF(Paramètres!$C$40=$C$5,Paramètres!$B$40,"")
B24: 18h–19h | C24: =IFERROR(IF(INDEX('J1 — VEN 18'!$C$5:$G$28,15,MATCH($C$5,'J1 — VEN 18'!$C$4:$G$4,0))="","",INDEX('J1 — VEN 18'!$C$5:$G$28,15,MATCH($C$5,'J1 — VEN 18'!$C$4:$G$4,0))),"") | D24: =IFERROR(IF(INDEX('J2 — SAM 19'!$C$5:$G$28,15,MATCH($C$5,'J2 — SAM 19'!$C$4:$G$4,0))="","",INDEX('J2 — SAM 19'!$C$5:$G$28,15,MATCH($C$5,'J2 — SAM 19'!$C$4:$G$4,0))),"") | J24: =IF(Paramètres!$C$41=$C$5,Paramètres!$B$41,"")
B25: 19h–20h | C25: =IFERROR(IF(INDEX('J1 — VEN 18'!$C$5:$G$28,16,MATCH($C$5,'J1 — VEN 18'!$C$4:$G$4,0))="","",INDEX('J1 — VEN 18'!$C$5:$G$28,16,MATCH($C$5,'J1 — VEN 18'!$C$4:$G$4,0))),"") | D25: =IFERROR(IF(INDEX('J2 — SAM 19'!$C$5:$G$28,16,MATCH($C$5,'J2 — SAM 19'!$C$4:$G$4,0))="","",INDEX('J2 — SAM 19'!$C$5:$G$28,16,MATCH($C$5,'J2 — SAM 19'!$C$4:$G$4,0))),"") | J25: =IF(Paramètres!$C$42=$C$5,Paramètres!$B$42,"")
B26: 20h–21h | C26: =IFERROR(IF(INDEX('J1 — VEN 18'!$C$5:$G$28,17,MATCH($C$5,'J1 — VEN 18'!$C$4:$G$4,0))="","",INDEX('J1 — VEN 18'!$C$5:$G$28,17,MATCH($C$5,'J1 — VEN 18'!$C$4:$G$4,0))),"") | D26: =IFERROR(IF(INDEX('J2 — SAM 19'!$C$5:$G$28,17,MATCH($C$5,'J2 — SAM 19'!$C$4:$G$4,0))="","",INDEX('J2 — SAM 19'!$C$5:$G$28,17,MATCH($C$5,'J2 — SAM 19'!$C$4:$G$4,0))),"") | J26: =IF(Paramètres!$C$43=$C$5,Paramètres!$B$43,"")
B27: 21h–22h | C27: =IFERROR(IF(INDEX('J1 — VEN 18'!$C$5:$G$28,18,MATCH($C$5,'J1 — VEN 18'!$C$4:$G$4,0))="","",INDEX('J1 — VEN 18'!$C$5:$G$28,18,MATCH($C$5,'J1 — VEN 18'!$C$4:$G$4,0))),"") | D27: =IFERROR(IF(INDEX('J2 — SAM 19'!$C$5:$G$28,18,MATCH($C$5,'J2 — SAM 19'!$C$4:$G$4,0))="","",INDEX('J2 — SAM 19'!$C$5:$G$28,18,MATCH($C$5,'J2 — SAM 19'!$C$4:$G$4,0))),"") | J27: =IF(Paramètres!$C$44=$C$5,Paramètres!$B$44,"")
B28: 22h–23h | C28: =IFERROR(IF(INDEX('J1 — VEN 18'!$C$5:$G$28,19,MATCH($C$5,'J1 — VEN 18'!$C$4:$G$4,0))="","",INDEX('J1 — VEN 18'!$C$5:$G$28,19,MATCH($C$5,'J1 — VEN 18'!$C$4:$G$4,0))),"") | D28: =IFERROR(IF(INDEX('J2 — SAM 19'!$C$5:$G$28,19,MATCH($C$5,'J2 — SAM 19'!$C$4:$G$4,0))="","",INDEX('J2 — SAM 19'!$C$5:$G$28,19,MATCH($C$5,'J2 — SAM 19'!$C$4:$G$4,0))),"") | J28: =IF(Paramètres!$C$45=$C$5,Paramètres!$B$45,"")
B29: 23h–00h | C29: =IFERROR(IF(INDEX('J1 — VEN 18'!$C$5:$G$28,20,MATCH($C$5,'J1 — VEN 18'!$C$4:$G$4,0))="","",INDEX('J1 — VEN 18'!$C$5:$G$28,20,MATCH($C$5,'J1 — VEN 18'!$C$4:$G$4,0))),"") | D29: =IFERROR(IF(INDEX('J2 — SAM 19'!$C$5:$G$28,20,MATCH($C$5,'J2 — SAM 19'!$C$4:$G$4,0))="","",INDEX('J2 — SAM 19'!$C$5:$G$28,20,MATCH($C$5,'J2 — SAM 19'!$C$4:$G$4,0))),"") | J29: =IF(Paramètres!$C$46=$C$5,Paramètres!$B$46,"")
B30: 00h–01h | C30: =IFERROR(IF(INDEX('J1 — VEN 18'!$C$5:$G$28,21,MATCH($C$5,'J1 — VEN 18'!$C$4:$G$4,0))="","",INDEX('J1 — VEN 18'!$C$5:$G$28,21,MATCH($C$5,'J1 — VEN 18'!$C$4:$G$4,0))),"") | D30: =IFERROR(IF(INDEX('J2 — SAM 19'!$C$5:$G$28,21,MATCH($C$5,'J2 — SAM 19'!$C$4:$G$4,0))="","",INDEX('J2 — SAM 19'!$C$5:$G$28,21,MATCH($C$5,'J2 — SAM 19'!$C$4:$G$4,0))),"") | J30: =IF(Paramètres!$C$47=$C$5,Paramètres!$B$47,"")
B31: 01h–02h | C31: =IFERROR(IF(INDEX('J1 — VEN 18'!$C$5:$G$28,22,MATCH($C$5,'J1 — VEN 18'!$C$4:$G$4,0))="","",INDEX('J1 — VEN 18'!$C$5:$G$28,22,MATCH($C$5,'J1 — VEN 18'!$C$4:$G$4,0))),"") | D31: =IFERROR(IF(INDEX('J2 — SAM 19'!$C$5:$G$28,22,MATCH($C$5,'J2 — SAM 19'!$C$4:$G$4,0))="","",INDEX('J2 — SAM 19'!$C$5:$G$28,22,MATCH($C$5,'J2 — SAM 19'!$C$4:$G$4,0))),"") | J31: =IF(Paramètres!$C$48=$C$5,Paramètres!$B$48,"")
B32: 02h–03h | C32: =IFERROR(IF(INDEX('J1 — VEN 18'!$C$5:$G$28,23,MATCH($C$5,'J1 — VEN 18'!$C$4:$G$4,0))="","",INDEX('J1 — VEN 18'!$C$5:$G$28,23,MATCH($C$5,'J1 — VEN 18'!$C$4:$G$4,0))),"") | D32: =IFERROR(IF(INDEX('J2 — SAM 19'!$C$5:$G$28,23,MATCH($C$5,'J2 — SAM 19'!$C$4:$G$4,0))="","",INDEX('J2 — SAM 19'!$C$5:$G$28,23,MATCH($C$5,'J2 — SAM 19'!$C$4:$G$4,0))),"") | J32: =IF(Paramètres!$C$49=$C$5,Paramètres!$B$49,"") -> Blanche
B33: 03h–04h | C33: =IFERROR(IF(INDEX('J1 — VEN 18'!$C$5:$G$28,24,MATCH($C$5,'J1 — VEN 18'!$C$4:$G$4,0))="","",INDEX('J1 — VEN 18'!$C$5:$G$28,24,MATCH($C$5,'J1 — VEN 18'!$C$4:$G$4,0))),"") | D33: =IFERROR(IF(INDEX('J2 — SAM 19'!$C$5:$G$28,24,MATCH($C$5,'J2 — SAM 19'!$C$4:$G$4,0))="","",INDEX('J2 — SAM 19'!$C$5:$G$28,24,MATCH($C$5,'J2 — SAM 19'!$C$4:$G$4,0))),"")

Sheet Récap équilibre
B2: RÉCAP — ÉQUILIBRE DES POSTES PAR ÉQUIPE
B3: Nombre d'heures passées à chaque poste, sur les deux jours. Se met à jour automatiquement quand tu modifies les onglets J1 / J2.
B5: POSTE | C5: =Paramètres!$B$6 -> Équipe 1 | D5: =Paramètres!$B$7 -> Équipe 2 | E5: =Paramètres!$B$8 -> Équipe 3 | F5: =Paramètres!$B$9 -> Équipe 4 | G5: =Paramètres!$B$10 -> Équipe 5 | H5: TOTAL
B6: =Paramètres!$G$6 -> SÉCU | C6: =COUNTIF('J1 — VEN 18'!C$5:C$28,$B6)+COUNTIF('J2 — SAM 19'!C$5:C$28,$B6) -> 3 | D6: =COUNTIF('J1 — VEN 18'!D$5:D$28,$B6)+COUNTIF('J2 — SAM 19'!D$5:D$28,$B6) -> 4 | E6: =COUNTIF('J1 — VEN 18'!E$5:E$28,$B6)+COUNTIF('J2 — SAM 19'!E$5:E$28,$B6) -> 4 | F6: =COUNTIF('J1 — VEN 18'!F$5:F$28,$B6)+COUNTIF('J2 — SAM 19'!F$5:F$28,$B6) -> 5 | G6: =COUNTIF('J1 — VEN 18'!G$5:G$28,$B6)+COUNTIF('J2 — SAM 19'!G$5:G$28,$B6) -> 5 | H6: =SUM(C6:G6) -> 21
B7: =Paramètres!$G$7 -> PLAINE | C7: =COUNTIF('J1 — VEN 18'!C$5:C$28,$B7)+COUNTIF('J2 — SAM 19'!C$5:C$28,$B7) -> 3 | D7: =COUNTIF('J1 — VEN 18'!D$5:D$28,$B7)+COUNTIF('J2 — SAM 19'!D$5:D$28,$B7) -> 7 | E7: =COUNTIF('J1 — VEN 18'!E$5:E$28,$B7)+COUNTIF('J2 — SAM 19'!E$5:E$28,$B7) -> 1 | F7: =COUNTIF('J1 — VEN 18'!F$5:F$28,$B7)+COUNTIF('J2 — SAM 19'!F$5:F$28,$B7) -> 0 | G7: =COUNTIF('J1 — VEN 18'!G$5:G$28,$B7)+COUNTIF('J2 — SAM 19'!G$5:G$28,$B7) -> 0 | H7: =SUM(C7:G7) -> 11
B8: =Paramètres!$G$8 -> SURVEILLANCE ACTIVITÉ | C8: =COUNTIF('J1 — VEN 18'!C$5:C$28,$B8)+COUNTIF('J2 — SAM 19'!C$5:C$28,$B8) -> 5 | D8: =COUNTIF('J1 — VEN 18'!D$5:D$28,$B8)+COUNTIF('J2 — SAM 19'!D$5:D$28,$B8) -> 3 | E8: =COUNTIF('J1 — VEN 18'!E$5:E$28,$B8)+COUNTIF('J2 — SAM 19'!E$5:E$28,$B8) -> 7 | F8: =COUNTIF('J1 — VEN 18'!F$5:F$28,$B8)+COUNTIF('J2 — SAM 19'!F$5:F$28,$B8) -> 3 | G8: =COUNTIF('J1 — VEN 18'!G$5:G$28,$B8)+COUNTIF('J2 — SAM 19'!G$5:G$28,$B8) -> 4 | H8: =SUM(C8:G8) -> 22
B9: =Paramètres!$G$9 -> PRÉPA OB | C9: =COUNTIF('J1 — VEN 18'!C$5:C$28,$B9)+COUNTIF('J2 — SAM 19'!C$5:C$28,$B9) -> 4 | D9: =COUNTIF('J1 — VEN 18'!D$5:D$28,$B9)+COUNTIF('J2 — SAM 19'!D$5:D$28,$B9) -> 2 | E9: =COUNTIF('J1 — VEN 18'!E$5:E$28,$B9)+COUNTIF('J2 — SAM 19'!E$5:E$28,$B9) -> 0 | F9: =COUNTIF('J1 — VEN 18'!F$5:F$28,$B9)+COUNTIF('J2 — SAM 19'!F$5:F$28,$B9) -> 0 | G9: =COUNTIF('J1 — VEN 18'!G$5:G$28,$B9)+COUNTIF('J2 — SAM 19'!G$5:G$28,$B9) -> 2 | H9: =SUM(C9:G9) -> 8
B10: =Paramètres!$G$10 -> REPAS | C10: =COUNTIF('J1 — VEN 18'!C$5:C$28,$B10)+COUNTIF('J2 — SAM 19'!C$5:C$28,$B10) -> 2 | D10: =COUNTIF('J1 — VEN 18'!D$5:D$28,$B10)+COUNTIF('J2 — SAM 19'!D$5:D$28,$B10) -> 0 | E10: =COUNTIF('J1 — VEN 18'!E$5:E$28,$B10)+COUNTIF('J2 — SAM 19'!E$5:E$28,$B10) -> 3 | F10: =COUNTIF('J1 — VEN 18'!F$5:F$28,$B10)+COUNTIF('J2 — SAM 19'!F$5:F$28,$B10) -> 3 | G10: =COUNTIF('J1 — VEN 18'!G$5:G$28,$B10)+COUNTIF('J2 — SAM 19'!G$5:G$28,$B10) -> 4 | H10: =SUM(C10:G10) -> 12
B11: =Paramètres!$G$11 -> BUVETTE | C11: =COUNTIF('J1 — VEN 18'!C$5:C$28,$B11)+COUNTIF('J2 — SAM 19'!C$5:C$28,$B11) -> 0 | D11: =COUNTIF('J1 — VEN 18'!D$5:D$28,$B11)+COUNTIF('J2 — SAM 19'!D$5:D$28,$B11) -> 0 | E11: =COUNTIF('J1 — VEN 18'!E$5:E$28,$B11)+COUNTIF('J2 — SAM 19'!E$5:E$28,$B11) -> 0 | F11: =COUNTIF('J1 — VEN 18'!F$5:F$28,$B11)+COUNTIF('J2 — SAM 19'!F$5:F$28,$B11) -> 0 | G11: =COUNTIF('J1 — VEN 18'!G$5:G$28,$B11)+COUNTIF('J2 — SAM 19'!G$5:G$28,$B11) -> 1 | H11: =SUM(C11:G11) -> 1
B12: =Paramètres!$G$12 -> NAVETTES | C12: =COUNTIF('J1 — VEN 18'!C$5:C$28,$B12)+COUNTIF('J2 — SAM 19'!C$5:C$28,$B12) -> 1 | D12: =COUNTIF('J1 — VEN 18'!D$5:D$28,$B12)+COUNTIF('J2 — SAM 19'!D$5:D$28,$B12) -> 0 | E12: =COUNTIF('J1 — VEN 18'!E$5:E$28,$B12)+COUNTIF('J2 — SAM 19'!E$5:E$28,$B12) -> 2 | F12: =COUNTIF('J1 — VEN 18'!F$5:F$28,$B12)+COUNTIF('J2 — SAM 19'!F$5:F$28,$B12) -> 1 | G12: =COUNTIF('J1 — VEN 18'!G$5:G$28,$B12)+COUNTIF('J2 — SAM 19'!G$5:G$28,$B12) -> 2 | H12: =SUM(C12:G12) -> 6
B13: =Paramètres!$G$13 -> PRÉCHECK | C13: =COUNTIF('J1 — VEN 18'!C$5:C$28,$B13)+COUNTIF('J2 — SAM 19'!C$5:C$28,$B13) -> 2 | D13: =COUNTIF('J1 — VEN 18'!D$5:D$28,$B13)+COUNTIF('J2 — SAM 19'!D$5:D$28,$B13) -> 2 | E13: =COUNTIF('J1 — VEN 18'!E$5:E$28,$B13)+COUNTIF('J2 — SAM 19'!E$5:E$28,$B13) -> 2 | F13: =COUNTIF('J1 — VEN 18'!F$5:F$28,$B13)+COUNTIF('J2 — SAM 19'!F$5:F$28,$B13) -> 2 | G13: =COUNTIF('J1 — VEN 18'!G$5:G$28,$B13)+COUNTIF('J2 — SAM 19'!G$5:G$28,$B13) -> 2 | H13: =SUM(C13:G13) -> 10
B14: =Paramètres!$G$19 -> MONTAGE / RANGEMENT | C14: =COUNTIF('J1 — VEN 18'!C$5:C$28,$B14)+COUNTIF('J2 — SAM 19'!C$5:C$28,$B14) -> 2 | D14: =COUNTIF('J1 — VEN 18'!D$5:D$28,$B14)+COUNTIF('J2 — SAM 19'!D$5:D$28,$B14) -> 2 | E14: =COUNTIF('J1 — VEN 18'!E$5:E$28,$B14)+COUNTIF('J2 — SAM 19'!E$5:E$28,$B14) -> 1 | F14: =COUNTIF('J1 — VEN 18'!F$5:F$28,$B14)+COUNTIF('J2 — SAM 19'!F$5:F$28,$B14) -> 1 | G14: =COUNTIF('J1 — VEN 18'!G$5:G$28,$B14)+COUNTIF('J2 — SAM 19'!G$5:G$28,$B14) -> 1 | H14: =SUM(C14:G14) -> 7
B15: =Paramètres!$G$20 -> REPOS | C15: =COUNTIF('J1 — VEN 18'!C$5:C$28,$B15)+COUNTIF('J2 — SAM 19'!C$5:C$28,$B15) -> 11 | D15: =COUNTIF('J1 — VEN 18'!D$5:D$28,$B15)+COUNTIF('J2 — SAM 19'!D$5:D$28,$B15) -> 10 | E15: =COUNTIF('J1 — VEN 18'!E$5:E$28,$B15)+COUNTIF('J2 — SAM 19'!E$5:E$28,$B15) -> 6 | F15: =COUNTIF('J1 — VEN 18'!F$5:F$28,$B15)+COUNTIF('J2 — SAM 19'!F$5:F$28,$B15) -> 10 | G15: =COUNTIF('J1 — VEN 18'!G$5:G$28,$B15)+COUNTIF('J2 — SAM 19'!G$5:G$28,$B15) -> 9 | H15: =SUM(C15:G15) -> 46
B16: HEURES DE POSTE (hors repos) | C16: =SUM(C6:C15)-C15 -> 22 | D16: =SUM(D6:D15)-D15 -> 20 | E16: =SUM(E6:E15)-E15 -> 20 | F16: =SUM(F6:F15)-F15 -> 15 | G16: =SUM(G6:G15)-G15 -> 21 | H16: =SUM(C16:G16) -> 98
B18: Écart max entre équipes (heures de poste) : | E18: =MAX(C16:G16)-MIN(C16:G16) -> 7
